[100.135803223] 2019-06-21 17:02:38,077 - INFO - launcher: Starting sanity checks
[100.828647614] 2019-06-21 17:02:38,078 - INFO - launcher: Checking for Python 3.5+
[101.253747940] 2019-06-21 17:02:38,078 - INFO - launcher: Checking console encoding
[101.650714874] 2019-06-21 17:02:38,078 - INFO - launcher: Ensuring we're in the right environment
[1077.641487122] 2019-06-21 17:02:39,054 - INFO - launcher: Required checks passed.
[1078.486442566] 2019-06-21 17:02:39,055 - INFO - launcher: Optional checks passed.
[1078.990221024] 2019-06-21 17:02:39,056 - INFO - launcher: Moving old musicbot log

######################### PRE-RUN SANITY CHECKS PASSED #########################

[2.5140705108642578] 2019-06-21 17:02:40,491 - WARNING - musicbot.config | In config.py::MainThread(1996390400), line 120 in run_checks: i18n file does not exist. Trying to fallback to config/i18n/en.json.
[2.5146889686584473] 2019-06-21 17:02:40,491 - INFO - musicbot.config | In config.py::MainThread(1996390400), line 131 in run_checks: Using i18n: config/i18n/en.json
[2.5220897197723389] 2019-06-21 17:02:40,499 - DEBUG - musicbot.bot | In bot.py::MainThread(1996390400), line 226 in _setup_logging: Set logging level to INFO
[2.5328824520111084] 2019-06-21 17:02:40,510 - DEBUG - musicbot.json | In json.py::MainThread(1996390400), line 8 in __init__: Init JSON obj with config/i18n/en.json
[2.5678122043609619] 2019-06-21 17:02:40,545 - INFO - musicbot.bot | In bot.py::MainThread(1996390400), line 91 in __init__: Starting MusicBot release-120519
[2.5688869953155518] 2019-06-21 17:02:40,546 - INFO - musicbot.bot | In bot.py::MainThread(1996390400), line 97 in __init__: Loaded autoplaylist with 2529 entries
[2.7766962051391602] 2019-06-21 17:02:40,753 - DEBUG - musicbot.spotify | In spotify.py::MainThread(1996390400), line 74 in get_token: Created a new access token: {'access_token': 'BQB31w_wyscN816OUXhV-pBUX-wv6lIPzRr9nUUzOxY6-i4UFlH88RpQSijuKdIQS6u7kwKb_Y2E5Fpjux0', 'token_type': 'Bearer', 'expires_in': 3600, 'scope': '', 'expires_at': 1561132960}
[2.7774097919464111] 2019-06-21 17:02:40,754 - INFO - musicbot.bot | In bot.py::MainThread(1996390400), line 122 in __init__: Authenticated with Spotify successfully using client ID and secret.
[5.6017582416534424] 2019-06-21 17:02:43,578 - DEBUG - musicbot.bot | In bot.py::MainThread(1996390400), line 949 in on_ready: Connection established, ready to go.
[5.6027343273162842] 2019-06-21 17:02:43,579 - DEBUG - musicbot.bot | In bot.py::MainThread(1996390400), line 340 in _cache_app_info: Caching app info
[5.7664926052093506] 2019-06-21 17:02:43,743 - DEBUG - musicbot.bot | In bot.py::MainThread(1996390400), line 771 in _scheck_ensure_env: Ensuring data folders exist
[5.7690682411193848] 2019-06-21 17:02:43,746 - DEBUG - musicbot.bot | In bot.py::MainThread(1996390400), line 787 in _scheck_server_permissions: Checking server permissions
[5.7698342800140381] 2019-06-21 17:02:43,747 - DEBUG - musicbot.bot | In bot.py::MainThread(1996390400), line 791 in _scheck_autoplaylist: Auditing autoplaylist
[5.7706227302551270] 2019-06-21 17:02:43,747 - DEBUG - musicbot.bot | In bot.py::MainThread(1996390400), line 795 in _scheck_configs: Validating config
[5.7712361812591553] 2019-06-21 17:02:43,748 - DEBUG - musicbot.config | In config.py::MainThread(1996390400), line 228 in async_validate: Validating options...
[5.7718861103057861] 2019-06-21 17:02:43,749 - DEBUG - musicbot.config | In config.py::MainThread(1996390400), line 242 in async_validate: Acquired owner id via API
[5.7724728584289551] 2019-06-21 17:02:43,749 - DEBUG - musicbot.bot | In bot.py::MainThread(1996390400), line 798 in _scheck_configs: Validating permissions config
[5.7730703353881836] 2019-06-21 17:02:43,750 - DEBUG - musicbot.permissions | In permissions.py::MainThread(1996390400), line 94 in async_validate: Validating permissions...
[5.7737069129943848] 2019-06-21 17:02:43,750 - DEBUG - musicbot.permissions | In permissions.py::MainThread(1996390400), line 98 in async_validate: Fixing automatic owner group
[5.7743139266967773] 2019-06-21 17:02:43,751 - INFO - musicbot.bot | In bot.py::MainThread(1996390400), line 966 in on_ready: Connected: 585508575057674250/RTD#7091
[5.7760756015777588] 2019-06-21 17:02:43,753 - INFO - musicbot.bot | In bot.py::MainThread(1996390400), line 974 in on_ready: Owner:     303933744971251713/MrGameX#5574

[5.7777819633483887] 2019-06-21 17:02:43,754 - INFO - musicbot.bot | In bot.py::MainThread(1996390400), line 977 in on_ready: Guild List:
[5.7792520523071289] 2019-06-21 17:02:43,756 - INFO - musicbot.bot | In bot.py::MainThread(1996390400), line 981 in on_ready:  - RTD_Team
[5.7810666561126709] 2019-06-21 17:02:43,758 - INFO - musicbot.bot | In bot.py::MainThread(1996390400), line 1037 in on_ready: Not bound to any text channels
[5.7825512886047363] 2019-06-21 17:02:43,759 - INFO - musicbot.bot | In bot.py::MainThread(1996390400), line 1063 in on_ready: Not autojoining any voice channels
[7.1809198856353760] 2019-06-21 17:02:45,158 - INFO - musicbot.bot | In bot.py::MainThread(1996390400), line 2692 in on_message: 303933744971251713/MrGameX#5574: !summon
[7.6271879673004150] 2019-06-21 17:02:45,604 - INFO - musicbot.bot | In bot.py::MainThread(1996390400), line 1926 in cmd_summon: Joining RTD_Team/CS class√©
[7.6403162479400635] 2019-06-21 17:02:45,617 - DEBUG - musicbot.bot | In bot.py::MainThread(1996390400), line 530 in on_player_stop: Running on_player_stop
[11.5245075225830078] 2019-06-21 17:02:49,501 - INFO - musicbot.bot | In bot.py::MainThread(1996390400), line 2692 in on_message: 303933744971251713/MrGameX#5574: !play 2th
[17.0746347904205322] 2019-06-21 17:02:55,051 - ERROR - musicbot.bot | In bot.py::MainThread(1996390400), line 2821 in on_message: Error in play: CommandError: [0;31mERROR:[0m Signature extraction failed: Traceback (most recent call last):
  File "/usr/local/opt/python-3.7.0/lib/python3.7/site-packages/youtube_dl/extractor/youtube.py", line 1342, in _decrypt_signature
    video_id, player_url, s
  File "/usr/local/opt/python-3.7.0/lib/python3.7/site-packages/youtube_dl/extractor/youtube.py", line 1250, in _extract_signature_function
    res = self._parse_sig_js(code)
  File "/usr/local/opt/python-3.7.0/lib/python3.7/site-packages/youtube_dl/extractor/youtube.py", line 1314, in _parse_sig_js
    jscode, 'Initial JS player signature function name', group='sig')
  File "/usr/local/opt/python-3.7.0/lib/python3.7/site-packages/youtube_dl/extractor/common.py", line 1005, in _search_regex
    raise RegexNotFoundError('Unable to extract %s' % _name)
youtube_dl.utils.RegexNotFoundError: Unable to extract [0;34mInitial JS player signature function name[0m
 (caused by RegexNotFoundError('Unable to extract \x1b[0;34mInitial JS player signature function name\x1b[0m'))
Traceback (most recent call last):
  File "/usr/local/opt/python-3.7.0/lib/python3.7/site-packages/youtube_dl/extractor/youtube.py", line 1342, in _decrypt_signature
    video_id, player_url, s
  File "/usr/local/opt/python-3.7.0/lib/python3.7/site-packages/youtube_dl/extractor/youtube.py", line 1250, in _extract_signature_function
    res = self._parse_sig_js(code)
  File "/usr/local/opt/python-3.7.0/lib/python3.7/site-packages/youtube_dl/extractor/youtube.py", line 1314, in _parse_sig_js
    jscode, 'Initial JS player signature function name', group='sig')
  File "/usr/local/opt/python-3.7.0/lib/python3.7/site-packages/youtube_dl/extractor/common.py", line 1005, in _search_regex
    raise RegexNotFoundError('Unable to extract %s' % _name)
youtube_dl.utils.RegexNotFoundError: Unable to extract [0;34mInitial JS player signature function name[0m

During handling of the above exception, another exception occurred:

Traceback (most recent call last):
  File "/usr/local/opt/python-3.7.0/lib/python3.7/site-packages/youtube_dl/YoutubeDL.py", line 796, in extract_info
    ie_result = ie.extract(url)
  File "/usr/local/opt/python-3.7.0/lib/python3.7/site-packages/youtube_dl/extractor/common.py", line 530, in extract
    ie_result = self._real_extract(url)
  File "/usr/local/opt/python-3.7.0/lib/python3.7/site-packages/youtube_dl/extractor/youtube.py", line 1986, in _real_extract
    encrypted_sig, video_id, player_url, age_gate)
  File "/usr/local/opt/python-3.7.0/lib/python3.7/site-packages/youtube_dl/extractor/youtube.py", line 1352, in _decrypt_signature
    'Signature extraction failed: ' + tb, cause=e)
youtube_dl.utils.ExtractorError: Signature extraction failed: Traceback (most recent call last):
  File "/usr/local/opt/python-3.7.0/lib/python3.7/site-packages/youtube_dl/extractor/youtube.py", line 1342, in _decrypt_signature
    video_id, player_url, s
  File "/usr/local/opt/python-3.7.0/lib/python3.7/site-packages/youtube_dl/extractor/youtube.py", line 1250, in _extract_signature_function
    res = self._parse_sig_js(code)
  File "/usr/local/opt/python-3.7.0/lib/python3.7/site-packages/youtube_dl/extractor/youtube.py", line 1314, in _parse_sig_js
    jscode, 'Initial JS player signature function name', group='sig')
  File "/usr/local/opt/python-3.7.0/lib/python3.7/site-packages/youtube_dl/extractor/common.py", line 1005, in _search_regex
    raise RegexNotFoundError('Unable to extract %s' % _name)
youtube_dl.utils.RegexNotFoundError: Unable to extract [0;34mInitial JS player signature function name[0m
 (caused by RegexNotFoundError('Unable to extract \x1b[0;34mInitial JS player signature function name\x1b[0m'))

During handling of the above exception, another exception occurred:

Traceback (most recent call last):
  File "/home/pi/Documents/Bot/RTD/musicbot/bot.py", line 1399, in cmd_play
    info_process = await self.downloader.extract_info(player.playlist.loop, song_url, download=False)
  File "/home/pi/Documents/Bot/RTD/musicbot/downloader.py", line 84, in extract_info
    return await loop.run_in_executor(self.thread_pool, functools.partial(self.unsafe_ytdl.extract_info, *args, **kwargs))
  File "/usr/local/opt/python-3.7.0/lib/python3.7/concurrent/futures/thread.py", line 57, in run
    result = self.fn(*self.args, **self.kwargs)
  File "/usr/local/opt/python-3.7.0/lib/python3.7/site-packages/youtube_dl/YoutubeDL.py", line 807, in extract_info
    return self.process_ie_result(ie_result, download, extra_info)
  File "/usr/local/opt/python-3.7.0/lib/python3.7/site-packages/youtube_dl/YoutubeDL.py", line 868, in process_ie_result
    extra_info=extra_info)
  File "/usr/local/opt/python-3.7.0/lib/python3.7/site-packages/youtube_dl/YoutubeDL.py", line 807, in extract_info
    return self.process_ie_result(ie_result, download, extra_info)
  File "/usr/local/opt/python-3.7.0/lib/python3.7/site-packages/youtube_dl/YoutubeDL.py", line 1006, in process_ie_result
    extra_info=extra)
  File "/usr/local/opt/python-3.7.0/lib/python3.7/site-packages/youtube_dl/YoutubeDL.py", line 868, in process_ie_result
    extra_info=extra_info)
  File "/usr/local/opt/python-3.7.0/lib/python3.7/site-packages/youtube_dl/YoutubeDL.py", line 819, in extract_info
    self.report_error(compat_str(e), e.format_traceback())
  File "/usr/local/opt/python-3.7.0/lib/python3.7/site-packages/youtube_dl/YoutubeDL.py", line 624, in report_error
    self.trouble(error_message, tb)
  File "/usr/local/opt/python-3.7.0/lib/python3.7/site-packages/youtube_dl/YoutubeDL.py", line 594, in trouble
    raise DownloadError(message, exc_info)
youtube_dl.utils.DownloadError: [0;31mERROR:[0m Signature extraction failed: Traceback (most recent call last):
  File "/usr/local/opt/python-3.7.0/lib/python3.7/site-packages/youtube_dl/extractor/youtube.py", line 1342, in _decrypt_signature
    video_id, player_url, s
  File "/usr/local/opt/python-3.7.0/lib/python3.7/site-packages/youtube_dl/extractor/youtube.py", line 1250, in _extract_signature_function
    res = self._parse_sig_js(code)
  File "/usr/local/opt/python-3.7.0/lib/python3.7/site-packages/youtube_dl/extractor/youtube.py", line 1314, in _parse_sig_js
    jscode, 'Initial JS player signature function name', group='sig')
  File "/usr/local/opt/python-3.7.0/lib/python3.7/site-packages/youtube_dl/extractor/common.py", line 1005, in _search_regex
    raise RegexNotFoundError('Unable to extract %s' % _name)
youtube_dl.utils.RegexNotFoundError: Unable to extract [0;34mInitial JS player signature function name[0m
 (caused by RegexNotFoundError('Unable to extract \x1b[0;34mInitial JS player signature function name\x1b[0m'))

During handling of the above exception, another exception occurred:

Traceback (most recent call last):
  File "/home/pi/Documents/Bot/RTD/musicbot/bot.py", line 2799, in on_message
    response = await handler(**handler_kwargs)
  File "/home/pi/Documents/Bot/RTD/musicbot/bot.py", line 1418, in cmd_play
    raise exceptions.CommandError(e, expire_in=30)
musicbot.exceptions.CommandError: [0;31mERROR:[0m Signature extraction failed: Traceback (most recent call last):
  File "/usr/local/opt/python-3.7.0/lib/python3.7/site-packages/youtube_dl/extractor/youtube.py", line 1342, in _decrypt_signature
    video_id, player_url, s
  File "/usr/local/opt/python-3.7.0/lib/python3.7/site-packages/youtube_dl/extractor/youtube.py", line 1250, in _extract_signature_function
    res = self._parse_sig_js(code)
  File "/usr/local/opt/python-3.7.0/lib/python3.7/site-packages/youtube_dl/extractor/youtube.py", line 1314, in _parse_sig_js
    jscode, 'Initial JS player signature function name', group='sig')
  File "/usr/local/opt/python-3.7.0/lib/python3.7/site-packages/youtube_dl/extractor/common.py", line 1005, in _search_regex
    raise RegexNotFoundError('Unable to extract %s' % _name)
youtube_dl.utils.RegexNotFoundError: Unable to extract [0;34mInitial JS player signature function name[0m
 (caused by RegexNotFoundError('Unable to extract \x1b[0;34mInitial JS player signature function name\x1b[0m'))
[20905.9525923728942871] 2019-06-21 22:51:03,929 - DEBUG - musicbot.bot | In bot.py::MainThread(1996390400), line 2960 in on_guild_available: Guild "RTD_Team" has become available.
[20907.9378738403320312] 2019-06-21 22:51:05,915 - DEBUG - musicbot.bot | In bot.py::MainThread(1996390400), line 949 in on_ready: Connection established, ready to go.
[20907.9387714862823486] 2019-06-21 22:51:05,915 - DEBUG - musicbot.bot | In bot.py::MainThread(1996390400), line 954 in on_ready: Received additional READY event, may have failed to resume
